Workbook

Sheet Hoja1
B2: SUBESTACIONES SEGUIMIENTO
B3: SUB-Proyecto | C3: Centro de costo | D3: Codigo del documento | E3: Documento | F3: Responsable | G3: Cargo | H3: Fecha y hora de incio | I3: Fecha y hora de Fin | J3: Horas | K3: Observaciones
B4: SE LOCERIA AMPLIACION L3 | C4: EDM 23136-101 | F4: JESUS DANIEL MENDOZA MERIÑO | G4: =+VLOOKUP(Tabla1[[#This Row],[Responsable]],Hoja2!$B$19:$C$36,2,FALSE) -> PRACTICANTE ME | H4: 46167.312 | I4: 46167.5 | J4: =+(Tabla1[[#This Row],[Fecha y hora de Fin]]-Tabla1[[#This Row],[Fecha y hora de incio]])*24 -> 4.5
C5: EDM 23136-101 | D5: NATURGY | E5: NATURGY | F5: ELKIN DAVID GUTIERREZ CAMPO | G5: =+VLOOKUP(Tabla1[[#This Row],[Responsable]],Hoja2!$B$19:$C$36,2,FALSE) -> BIM | J5: =+(Tabla1[[#This Row],[Fecha y hora de Fin]]-Tabla1[[#This Row],[Fecha y hora de incio]])*24 -> 0
B6: SE LOCERIA AMPLIACION L3 | C6: EDM 23136-101 | D6: SE-ALOCL3-ISES-AMP-PRE-ME- 00001 | E6: PRESUPUESTO COMPONENTE ELECTROMECÁNICO | F6: BRAYAN DASAEV REALES VELASQUEZ | G6: =+VLOOKUP(Tabla1[[#This Row],[Responsable]],Hoja2!$B$19:$C$36,2,FALSE) -> PRACTICANTE ME | H6: 46167.312 | I6: 46167.618 | J6: =+(Tabla1[[#This Row],[Fecha y hora de Fin]]-Tabla1[[#This Row],[Fecha y hora de incio]])*24 -> 7.3333333 | K6: ATENCION DE INCIDENCIAS
B7: SE METALCLAD LOCERIA | C7: EDM 23136-101 | D7: SE-MC3LOC-ISES-AMP-M3D-OC-40000 | E7: CANALIZACIONES | F7: RENY TATIANA OLARTE LOBO | G7: =+VLOOKUP(Tabla1[[#This Row],[Responsable]],Hoja2!$B$19:$C$36,2,FALSE) -> MODELADOR OC | H7: 46167.312 | I7: 46167.75 | J7: =+(Tabla1[[#This Row],[Fecha y hora de Fin]]-Tabla1[[#This Row],[Fecha y hora de incio]])*24 -> 10.5 | K7: ATENCION DE INCIDENCIAS
B8: SE LOCERIA AMPLIACION L3 | C8: EDM 23136-101 | D8: SE-ALOCL3-ISES-AMP-M3D-OC-00007 | E8: CIMENTACION REACTOR | F8: JUAN JOSE GUTIERREZ DE LA HOZ | G8: =+VLOOKUP(Tabla1[[#This Row],[Responsable]],Hoja2!$B$19:$C$36,2,FALSE) -> MODELADOR OC | H8: 46167.312 | I8: 46167.524 | J8: =+(Tabla1[[#This Row],[Fecha y hora de Fin]]-Tabla1[[#This Row],[Fecha y hora de incio]])*24 -> 5.0833333 | K8: ATENCION DE INCIDENCIAS
B9: SE LOCERIA AMPLIACION L3 | C9: EDM 23136-101 | D9: SE-ALOCL3-ISES-AMP-M3D-OC-00008 | E9: CIMENTACION ESTRUCTURA SOPORTE DE CABLES REACTOR | F9: JUAN JOSE GUTIERREZ DE LA HOZ | G9: =+VLOOKUP(Tabla1[[#This Row],[Responsable]],Hoja2!$B$19:$C$36,2,FALSE) -> MODELADOR OC | H9: 46167.524 | I9: 46167.639 | J9: =+(Tabla1[[#This Row],[Fecha y hora de Fin]]-Tabla1[[#This Row],[Fecha y hora de incio]])*24 -> 2.75 | K9: ATENCION DE INCIDENCIAS
B10: SE METALCLAD LOCERIA | C10: EDM 23136-101 | D10: SE-MC3LOC-ISES-AMP-MC-ME-40005 | E10: MEMORIA SERVICIO AUXILIARES | F10: LUIS EDUARDO VEGA ARIZA | G10: =+VLOOKUP(Tabla1[[#This Row],[Responsable]],Hoja2!$B$19:$C$36,2,FALSE) -> INGENIERO ME | H10: 46167.583 | I10: 46167.618 | J10: =+(Tabla1[[#This Row],[Fecha y hora de Fin]]-Tabla1[[#This Row],[Fecha y hora de incio]])*24 -> 0.83333333 | K10: ATENCION DE INCIDENCIAS DEL 5 MAYO 2026
B11: TURBACO AFINIA | C11: AFN24102-100 | F11: ALEX SANTIAGO RODRIGUEZ | G11: =+VLOOKUP(Tabla1[[#This Row],[Responsable]],Hoja2!$B$19:$C$36,2,FALSE) -> MODELADOR OC | H11: 46167.312 | I11: 46169.75 | J11: =+(Tabla1[[#This Row],[Fecha y hora de Fin]]-Tabla1[[#This Row],[Fecha y hora de incio]])*24 -> 58.5 | K11: ATENCION A COMENTARIOS GENERALES
B12: SE METALCLAD LOCERIA | C12: EDM 23136-101 | D12: SE-MC3LOC-ISES-AMP-M3D-ME-40000 | E12: SOPORTE DE CABLES Y BANDEJAS | F12: LUIS FERNANDO ZABALETA GONZALEZ | G12: =+VLOOKUP(Tabla1[[#This Row],[Responsable]],Hoja2!$B$19:$C$36,2,FALSE) -> MODELADOR ME | H12: 46164.312 | I12: 46164.562 | J12: =+(Tabla1[[#This Row],[Fecha y hora de Fin]]-Tabla1[[#This Row],[Fecha y hora de incio]])*24 -> 6 | K12: ATENCION DE INCIDENCIAS
B13: SE METALCLAD LOCERIA | C13: EDM 23136-101 | D13: SE-MC3LOC-ISES-AMP-M3D-ME-30000 | E13: MODELO GENERAL | F13: LUIS FERNANDO ZABALETA GONZALEZ | G13: =+VLOOKUP(Tabla1[[#This Row],[Responsable]],Hoja2!$B$19:$C$36,2,FALSE) -> MODELADOR ME | H13: 46167.312 | I13: 46167.75 | J13: =+(Tabla1[[#This Row],[Fecha y hora de Fin]]-Tabla1[[#This Row],[Fecha y hora de incio]])*24 -> 10.5 | K13: ATENCION DE INCIDENCIAS
B14: SE METALCLAD LOCERIA | C14: EDM 23136-101 | D14: SE-MC3LOC-ISES-AMP-M3D-ME-30000 | E14: MODELO GENERAL | F14: LUIS FERNANDO ZABALETA GONZALEZ | G14: =+VLOOKUP(Tabla1[[#This Row],[Responsable]],Hoja2!$B$19:$C$36,2,FALSE) -> MODELADOR ME | H14: 46168.312 | I14: 46168.75 | J14: =+(Tabla1[[#This Row],[Fecha y hora de Fin]]-Tabla1[[#This Row],[Fecha y hora de incio]])*24 -> 10.5 | K14: ATENCION DE INCIDENCIAS
B15: LAT 230 SANTIAGO | C15: EDM 23136-101 | D15: LAT-SGO2-ISES-NEW-PL-OC-00001 | E15: PLANO TOPOGRAFICO | F15: ALEJANDRO DAZA BERNAL | G15: =+VLOOKUP(Tabla1[[#This Row],[Responsable]],Hoja2!$B$19:$C$36,2,FALSE) -> MODELADOR OC | H15: 46167.312 | I15: 46167.75 | J15: =+(Tabla1[[#This Row],[Fecha y hora de Fin]]-Tabla1[[#This Row],[Fecha y hora de incio]])*24 -> 10.5 | K15: ATENCION A COMENTARIOS
B16: SE METALCLAD LOCERIA | C16: EDM 23136-101 | D16: SE-MC3LOC-ISES-AMP-ET-ME-10009 | E16: ET UCI - FE UCI | F16: BRAYAN DASAEV REALES VELASQUEZ | G16: =+VLOOKUP(Tabla1[[#This Row],[Responsable]],Hoja2!$B$19:$C$36,2,FALSE) -> PRACTICANTE ME | H16: 46167.631 | I16: 46167.75 | J16: =+(Tabla1[[#This Row],[Fecha y hora de Fin]]-Tabla1[[#This Row],[Fecha y hora de incio]])*24 -> 2.8666667 | K16: ATENCION A COMENTARIOS
B17: SE SAN FRANCISCO | C17: EDM 23136-101 | D17: SE-MC2SFC-ISES-NEW-M3D-ME-30000 | E17: MODELO GENERAL- BASICA | F17: CRISTIAN DAVID FABREGAS BLANCO | G17: =+VLOOKUP(Tabla1[[#This Row],[Responsable]],Hoja2!$B$19:$C$36,2,FALSE) -> MODELADOR ME | H17: 46163.312 | I17: 46163.75 | J17: =+(Tabla1[[#This Row],[Fecha y hora de Fin]]-Tabla1[[#This Row],[Fecha y hora de incio]])*24 -> 10.5 | K17: ATENCION DE INCIDENCIAS
B18: SE LOCERIA AMPLIACION L3 | C18: EDM 23136-101 | D18: SE-ALOCL3-ISES-AMP-M3D-ME- 00001 | E18: MODELO GENERAL | F18: CRISTIAN DAVID FABREGAS BLANCO | G18: =+VLOOKUP(Tabla1[[#This Row],[Responsable]],Hoja2!$B$19:$C$36,2,FALSE) -> MODELADOR ME | H18: 46164.312 | I18: 46164.562 | J18: =+(Tabla1[[#This Row],[Fecha y hora de Fin]]-Tabla1[[#This Row],[Fecha y hora de incio]])*24 -> 6 | K18: ATENCION DE INCIDENCIAS
B19: SE SAN FRANCISCO | C19: EDM 23136-101 | D19: SE-MC2SFC-ISES-NEW-M3D-ME-30000 | E19: MODELO GENERAL- BASICA | F19: CRISTIAN DAVID FABREGAS BLANCO | G19: =+VLOOKUP(Tabla1[[#This Row],[Responsable]],Hoja2!$B$19:$C$36,2,FALSE) -> MODELADOR ME | H19: 46167.312 | I19: 46167.542 | J19: =+(Tabla1[[#This Row],[Fecha y hora de Fin]]-Tabla1[[#This Row],[Fecha y hora de incio]])*24 -> 5.5 | K19: ATENCION DE INCIDENCIAS
B20: SE LOCERIA AMPLIACION L3 | C20: EDM 23136-101 | D20: SE-ALOCL3-ISES-AMP-M3D-ME- 00001 | E20: MODELO GENERAL | F20: CRISTIAN DAVID FABREGAS BLANCO | G20: =+VLOOKUP(Tabla1[[#This Row],[Responsable]],Hoja2!$B$19:$C$36,2,FALSE) -> MODELADOR ME | H20: 46167.542 | I20: 46167.75 | J20: =+(Tabla1[[#This Row],[Fecha y hora de Fin]]-Tabla1[[#This Row],[Fecha y hora de incio]])*24 -> 5 | K20: ATENCION DE INCIDENCIAS
B21: SE METALCLAD LOCERIA | C21: EDM 23136-101 | D21: SE-MC3LOC-ISES-AMP-ET-ME-10009 | E21: ET UCI - FE UCI | F21: LUIS EDUARDO VEGA ARIZA | G21: =+VLOOKUP(Tabla1[[#This Row],[Responsable]],Hoja2!$B$19:$C$36,2,FALSE) -> INGENIERO ME | H21: 46167.618 | I21: 46167.635 | J21: =+(Tabla1[[#This Row],[Fecha y hora de Fin]]-Tabla1[[#This Row],[Fecha y hora de incio]])*24 -> 0.41666667 | K21: REVISION DE DOCUMENTOS
B22: TURBACO AFINIA | C22: AFN24102-100 | D22: SE-SIE-ME-PL-501 | E22: CORTES DE BANDEJAS SIERRA FLOR | F22: EDUARDO GUZMAN SANCHEZ | G22: =+VLOOKUP(Tabla1[[#This Row],[Responsable]],Hoja2!$B$19:$C$36,2,FALSE) -> MODELADOR ME | H22: 46167.312 | I22: 46167.75 | J22: =+(Tabla1[[#This Row],[Fecha y hora de Fin]]-Tabla1[[#This Row],[Fecha y hora de incio]])*24 -> 10.5 | K22: ADICION DE CORTES NUEVOS A PLANO DE CORTES DE BANDEJAS
B23: LAT 230 SANTIAGO | C23: AFN24102-100 | D23: SE-PUL-ME-PL-309 | E23: ATENCION DE COMENTARIOS P LIBERTADOR | F23: EDUARDO GUZMAN SANCHEZ | G23: =+VLOOKUP(Tabla1[[#This Row],[Responsable]],Hoja2!$B$19:$C$36,2,FALSE) -> MODELADOR ME | H23: 46168.312 | I23: 46170.75 | J23: =+(Tabla1[[#This Row],[Fecha y hora de Fin]]-Tabla1[[#This Row],[Fecha y hora de incio]])*24 -> 58.5 | K23: ATENCION DE COMENTARIOS GENERALES.
... B46: LAT CHORRERA | C46: EDM 23136-101 | D46: LAT-CHOTR2-ISES-NEW-M3D-OC-10000 | E46: MODELO GENERAL | F46: CAMILO GALVEZ OSORIO | G46: =+VLOOKUP(Tabla1[[#This Row],[Responsable]],Hoja2!$B$19:$C$36,2,FALSE) -> MODELADOR OC | H46: 46167.312 | I46: 46167.75 | J46: =+(Tabla1[[#This Row],[Fecha y hora de Fin]]-Tabla1[[#This Row],[Fecha y hora de incio]])*24 -> 10.5 | K46: APOYO PARA AJUSTE DE INFORMACION EN BASE A COMENTARIOS
B47: TURBACO AFINIA | C47: EDM 23136-101 | D47: SE-TUR-OC-PL-007-1 | E47: Plano de Demoliciones | F47: LEO TEKKEN GONCALVES | G47: =+VLOOKUP(Tabla1[[#This Row],[Responsable]],Hoja2!$B$19:$C$36,2,FALSE) -> MODELADOR OC | H47: 46167.583 | I47: 46168.583 | J47: =+(Tabla1[[#This Row],[Fecha y hora de Fin]]-Tabla1[[#This Row],[Fecha y hora de incio]])*24 -> 24
B48: SE METALCLAD LOCERIA | C48: EDM 23136-101 | D48: SE-MC3LOC-ISES-AMP-ET-ME-10000 | E48: ET MONTAJE ELECTROMECANICO | F48: BRAYAN DASAEV REALES VELASQUEZ | G48: =+VLOOKUP(Tabla1[[#This Row],[Responsable]],Hoja2!$B$19:$C$36,2,FALSE) -> PRACTICANTE ME | H48: 46168.326 | I48: 46168.375 | J48: =+(Tabla1[[#This Row],[Fecha y hora de Fin]]-Tabla1[[#This Row],[Fecha y hora de incio]])*24 -> 1.1666667 | K48: ATENCION A COMENTARIOS
B49: SE LOCERIA AMPLIACION L3 | C49: EDM 23136-101 | D49: SE-ALOCL3-ISES-AMP-ET-ME-00009 | E49: ET TRANSFORMADOR DE POTENCIA | F49: JESUS DANIEL MENDOZA MERIÑO | G49: =+VLOOKUP(Tabla1[[#This Row],[Responsable]],Hoja2!$B$19:$C$36,2,FALSE) -> PRACTICANTE ME | H49: 46168.41 | I49: 46168.431 | J49: =+(Tabla1[[#This Row],[Fecha y hora de Fin]]-Tabla1[[#This Row],[Fecha y hora de incio]])*24 -> 0.5 | K49: ATENCION A INCIDENCIAS
B50: SE LOCERIA AMPLIACION L3 | C50: EDM 23136-101 | D50: SE-ALOCL3-ISES-AMP-ET-ME-00019 | E50: ET TRANSFORMADOR DE SERVICIOS AUXILIARES | F50: JESUS DANIEL MENDOZA MERIÑO | G50: =+VLOOKUP(Tabla1[[#This Row],[Responsable]],Hoja2!$B$19:$C$36,2,FALSE) -> PRACTICANTE ME | H50: 46168.444 | I50: 46168.49 | J50: =+(Tabla1[[#This Row],[Fecha y hora de Fin]]-Tabla1[[#This Row],[Fecha y hora de incio]])*24 -> 1.0833333 | K50: ATENCION A INCIDENCIAS
B51: SE METALCLAD LOCERIA | C51: EDM 23136-101 | D51: SE-MC3LOC-ISES-AMP-ET-ME-10009 | E51: ET ARMARIO UCI | F51: JESUS DANIEL MENDOZA MERIÑO | G51: =+VLOOKUP(Tabla1[[#This Row],[Responsable]],Hoja2!$B$19:$C$36,2,FALSE) -> PRACTICANTE ME | H51: 46168.521 | I51: 46168.535 | J51: =+(Tabla1[[#This Row],[Fecha y hora de Fin]]-Tabla1[[#This Row],[Fecha y hora de incio]])*24 -> 0.33333333 | K51: ATENCION A COMENTARIOS
B52: SE METALCLAD LOCERIA | C52: EDM 23136-101 | D52: SE-MC3LOC-ISES-AMP-MC-ME-40004 | E52: MC CABLES AISLADOS MT | F52: BRAYAN DASAEV REALES VELASQUEZ | G52: =+VLOOKUP(Tabla1[[#This Row],[Responsable]],Hoja2!$B$19:$C$36,2,FALSE) -> PRACTICANTE ME | H52: 46168.5 | I52: 46168.535 | J52: =+(Tabla1[[#This Row],[Fecha y hora de Fin]]-Tabla1[[#This Row],[Fecha y hora de incio]])*24 -> 0.83333333 | K52: ATENCION A COMENTARIOS
B53: SE METALCLAD LOCERIA | C53: EDM 23136-101 | D53: SE-MC3LOC-ISES-AMP-MC-ME-40008 | E53: MC MALLA PUESTA A TIERRA | F53: BRAYAN DASAEV REALES VELASQUEZ | G53: =+VLOOKUP(Tabla1[[#This Row],[Responsable]],Hoja2!$B$19:$C$36,2,FALSE) -> PRACTICANTE ME | H53: 46168.583 | I53: 46168.625 | J53: =+(Tabla1[[#This Row],[Fecha y hora de Fin]]-Tabla1[[#This Row],[Fecha y hora de incio]])*24 -> 1 | K53: ATENCION A INCIDENCIAS
B54: LAT CHORRERA | C54: EDM 23136-101 | D54: LAT-CHOTR2-ISES-NEW-M3D-OC-00000 | E54: CÁMARAS - LÍNEAS - CAD - TOPOGRAFIA | F54: DICNEY RUIZ HERNANDEZ | G54: =+VLOOKUP(Tabla1[[#This Row],[Responsable]],Hoja2!$B$19:$C$36,2,FALSE) -> MODELADOR ME | H54: 46168.66 | I54: 46168.708 | J54: =+(Tabla1[[#This Row],[Fecha y hora de Fin]]-Tabla1[[#This Row],[Fecha y hora de incio]])*24 -> 1.1666667 | K54: AJUSTE PLANIMETRIA CAD PARA MODELOS 20001 A 20005
B55: LAT CHORRERA | C55: EDM 23136-101 | D55: LAT-CHOTR2-ISES-NEW-M3D-OC-00001 | E55: LÍNEA PROYECTADA SE TORNO - CG2 | F55: DICNEY RUIZ HERNANDEZ | G55: =+VLOOKUP(Tabla1[[#This Row],[Responsable]],Hoja2!$B$19:$C$36,2,FALSE) -> MODELADOR ME | H55: 46168.417 | I55: 46168.733 | J55: =+(Tabla1[[#This Row],[Fecha y hora de Fin]]-Tabla1[[#This Row],[Fecha y hora de incio]])*24 -> 7.6 | K55: MODELADO Y AJUSTE DE TUBERIA PHD
B56: LAT CHORRERA | C56: EDM 23136-101 | D56: LAT-CHOTR2-ISES-NEW-M3D-OC-00002 | E56: LÍNEA PROYECTADA CG2 - CG3 | F56: DICNEY RUIZ HERNANDEZ | G56: =+VLOOKUP(Tabla1[[#This Row],[Responsable]],Hoja2!$B$19:$C$36,2,FALSE) -> MODELADOR ME | H56: 46168.312 | I56: 46168.428 | J56: =+(Tabla1[[#This Row],[Fecha y hora de Fin]]-Tabla1[[#This Row],[Fecha y hora de incio]])*24 -> 2.7833333 | K56: MODELADO Y AJUSTE DE TUBERIA PHD
B57: LAT CHORRERA | C57: EDM 23136-101 | D57: LAT-CHOTR2-ISES-NEW-M3D-OC-20001 | E57: MODELO GENERAL PLANTA PERFIL TRAMO 1-2 | F57: DICNEY RUIZ HERNANDEZ | G57: =+VLOOKUP(Tabla1[[#This Row],[Responsable]],Hoja2!$B$19:$C$36,2,FALSE) -> MODELADOR ME | H57: 46168.619 | I57: 46168.757 | J57: =+(Tabla1[[#This Row],[Fecha y hora de Fin]]-Tabla1[[#This Row],[Fecha y hora de incio]])*24 -> 3.3 | K57: PLANIMETRIA
B58: BERRUGAS AFINIA | C58: EDM 23136-101 | D58: SE-BER-OC-PL-017 | E58: Sistema de red de incendios caseta | F58: LEO TEKKEN GONCALVES | G58: =+VLOOKUP(Tabla1[[#This Row],[Responsable]],Hoja2!$B$19:$C$36,2,FALSE) -> MODELADOR OC | H58: 46168.583 | I58: 46168.688 | J58: =+(Tabla1[[#This Row],[Fecha y hora de Fin]]-Tabla1[[#This Row],[Fecha y hora de incio]])*24 -> 2.5
B59: SE METALCLAD LOCERIA | C59: EDM 23136-101 | D59: SE-MC3LOC-ISES-AMP-ET-ME-10008 | E59: ET DE VARILLA DE PUESTA A TIERRA | F59: BRAYAN DASAEV REALES VELASQUEZ | G59: =+VLOOKUP(Tabla1[[#This Row],[Responsable]],Hoja2!$B$19:$C$36,2,FALSE) -> PRACTICANTE ME | H59: 46168.637 | I59: 46168.75 | J59: =+(Tabla1[[#This Row],[Fecha y hora de Fin]]-Tabla1[[#This Row],[Fecha y hora de incio]])*24 -> 2.7
B60: SE METALCLAD LOCERIA | C60: EDM 23136-101 | D60: SE-MC3LOC-ISES-AMP-ET-ME-10001 | E60: ET DE SHELTER O METAL CLAD | F60: JESUS DANIEL MENDOZA MERIÑO | G60: =+VLOOKUP(Tabla1[[#This Row],[Responsable]],Hoja2!$B$19:$C$36,2,FALSE) -> PRACTICANTE ME | H60: 46168.09 | I60: 46168.736 | J60: =+(Tabla1[[#This Row],[Fecha y hora de Fin]]-Tabla1[[#This Row],[Fecha y hora de incio]])*24 -> 15.5 | K60: ATENCION A COMENTARIOS
B61: TURBACO AFINIA | C61: AFN24102-100 | D61: SE-SIE-ME-PL-506 | E61: CORTES RUTA DE CABLES DE POTENCIA | F61: DIEGO PEREIRA IRIARTE | G61: =+VLOOKUP(Tabla1[[#This Row],[Responsable]],Hoja2!$B$19:$C$36,2,FALSE) -> MODELADOR OC | H61: 46168.312 | I61: 46168.75 | J61: =+(Tabla1[[#This Row],[Fecha y hora de Fin]]-Tabla1[[#This Row],[Fecha y hora de incio]])*24 -> 10.5 | K61: ATENCION A COMENTARIOS
B62: SE METALCLAD LOCERIA | C62: EDM 23136-101 | D62: SE-MC3LOC-ISES-AMP-MC-ME-40006 | E62: MC INSTALACIONES ELECTRICAS E ILUMINACIÓN | F62: BRAYAN DASAEV REALES VELASQUEZ | G62: =+VLOOKUP(Tabla1[[#This Row],[Responsable]],Hoja2!$B$19:$C$36,2,FALSE) -> PRACTICANTE ME | H62: 46169.312 | I62: 46169.438 | J62: =+(Tabla1[[#This Row],[Fecha y hora de Fin]]-Tabla1[[#This Row],[Fecha y hora de incio]])*24 -> 3
B63: SE METALCLAD LOCERIA | C63: EDM 23136-101 | D63: SE-MC3LOC-ISES-AMP-M3D-OC-40000 | E63: CANALIZACIONES | F63: RENY TATIANA OLARTE LOBO | G63: =+VLOOKUP(Tabla1[[#This Row],[Responsable]],Hoja2!$B$19:$C$36,2,FALSE) -> MODELADOR OC | H63: 46168.312 | I63: 46168.417 | J63: =+(Tabla1[[#This Row],[Fecha y hora de Fin]]-Tabla1[[#This Row],[Fecha y hora de incio]])*24 -> 2.5
...

Sheet Hoja2
B3: DISCIPLINA
B4: ME
B5: OC
B7: CARGOS
B8: ANALISTA ME
B9: ANALISTA OC
B10: PRACTICANTE ME
B11: PRACTICANTE OC
B12: MODELADOR OC
B13: BIM
B14: MODELADOR ME
B15: INGENIERO ME
... B18: RESPONSABLES
B19: JUAN JOSE GUTIERREZ DE LA HOZ | C19: MODELADOR OC
B20: CRISTIAN DAVID FABREGAS BLANCO | C20: MODELADOR ME
B21: LUIS FERNANDO ZABALETA GONZALEZ | C21: MODELADOR ME
B22: JESUS DANIEL MENDOZA MERIÑO | C22: PRACTICANTE ME
B23: BRAYAN DASAEV REALES VELASQUEZ | C23: PRACTICANTE ME
B24: CAMILO GALVEZ OSORIO | C24: MODELADOR OC
B25: DICNEY RUIZ HERNANDEZ | C25: MODELADOR ME
B26: DIEGO PEREIRA IRIARTE | C26: MODELADOR OC
B27: ORLANDO ANGULO BUSTILLOS | C27: MODELADOR ME
B28: LEO TEKKEN GONCALVES | C28: MODELADOR OC
B29: ALEJANDRO DAZA BERNAL | C29: MODELADOR OC
B30: EDUARDO GUZMAN SANCHEZ | C30: MODELADOR ME
... B36: RENY TATIANA OLARTE LOBO | C36: MODELADOR OC
B41: PROYECTOS
B42: SE LOCERIA AMPLIACION L3
B43: SE METALCLAD LOCERIA
B44: LAT 230 SANTIAGO
B45: LAT PANAMA III
B46: LAT LLANO SANCHEZ
B47: LAT CHORRERA
B48: LAT COCO 230KV
B49: SE SAN FRANCISCO
B50: SE ALMIRANTE II
B51: SE SANTIAGO II
B52: LAT JUSTO AROSEMENA
... B55: TURBACO AFINIA
A56: PUERTO ESCONDIDO AFINIA
...
